Workbook

Sheet Objetivos_calc
B1: DATOS PERSONALES | G1: RESULTADOS BASE | J1: 1.2 | K1: 0.3 | L1: 0.4 | M1: 0.3 | O1: 5 | P1: 14 | Q1: 0.1 | R1: 0.1 | S1: 3.5 | T1: AJUSTES USUARIO | AG1: RESULTADO AJUSTADO | AQ1: CONSUMO ACTIVIDAD | AZ1: OBJETIVOS DIARIOS | BD1: 5 | BE1: 14 | BF1: 0.1 | BG1: 0.1 | BH1: 3.5 | BJ1: APORTE ALIMENTACION | BV1: NUTRITIONAL SCORE
A2: case_id | B2: sex | C2: age | D2: height_cm | E2: weight_kg | G2: BMI | H2: BMR (Miffin) | J2: base_energy | K2: base_prote | L2: base_carboh | M2: base_fats | N2: base_calculated_energy | O2: base_salt | P2: base_fiber | Q2: base_sugar | R2: base_satfats | S2: base_processed | T2: tuning_energy | U2: tuning_prote | V2: tuning_carboh | W2: tuning_fats | X2: tuning_salt | Y2: tuning_fiber | Z2: tuning_sugar | AA2: tuning_satfats | AB2: tuning_processed | AC2: tuned_calculated_energy | AD2: tuned_calculated_prote | AE2: tuned_calculated_carboh | AF2: tuned_calculated_fats | AG2: tuned_prote | AH2: tuned_carboh | AI2: tuned_fats | AJ2: tuned_energy | AK2: tuned_salt | AL2: tuned_fiber | AM2: tuned_sugar | AN2: tuned_satfats | AO2: tuned_processed | AQ2: steps_activity | AR2: gym_activity | AS2: steps_total_energy | AT2: gym_total_energy | AV2: daily_calculated_energy | AW2: daily_calculated_prote | AX2: daily_calculated_carboh | AY2: daily_calculated_fats | AZ2: daily_prote | BA2: daily_carboh | BB2: daily_fats | BC2: daily_energy | BD2: daily_salt | BE2: daily_fiber | BF2: daily_sugar | BG2: daily_satfats | BH2: daily_processed | BJ2: menu_id | BK2: day_week | BL2: food_total_energy | BM2: food_total_prote | BN2: food_total_carboh | BO2: food_total_fats | BP2: food_total_satfats | BQ2: food_total_fiber | BR2: food_total_sugar | BS2: food_total_salt | BT2: food_total_processed | BV2: daily_dif_energy | BW2: daily_dif_prote | BX2: daily_dif_carboh | BY2: daily_dif_fats | BZ2: daily_dif_salt | CA2: daily_dif_fiber | CB2: daily_dif_sugar | CC2: daily_dif_satfats | CD2: daily_dif_processed | CE2: nutrition_score_penalty_energy | CF2: nutrition_score_penalty_prote | CG2: nutrition_score_penalty_carboh | CH2: nutrition_score_penalty_fats | CI2: nutrition_score_penalty_salt | CJ2: nutrition_score_penalty_fiber | CK2: nutrition_score_penalty_sugar | CL2: nutrition_score_penalty_satfats | CM2: nutrition_score_penalty_processed | CN2: nutrition_score
A3: TC01 | B3: hombre | C3: 30 | D3: 175 | E3: 75 | G3: {=IF(ISBLANK($A3:$A100),"", ROUND(E3:E100 / ((D3:D100 / 100) ^2),1))} -> 24.5 | H3: {=IF(ISBLANK($A3:$A100),"", ROUND(10*E3:E100 + 6.25*D3:D100 - 5*C3:C100 + IF(B3:B100="hombre", 5, -161),0))} -> 1699 | J3: {=IF(ISBLANK(A3:A100),"", ROUND(H3:H100 * $J$1,0))} -> 2039 | K3: {=IF(ISBLANK($A3:$A100),"", ROUND($J3:J100 * K$1 / 4,0))} -> 153 | L3: {=IF(ISBLANK($A3:$A100),"", ROUND($J3:J100 * L$1 / 4,0))} -> 204 | M3: {=IF(ISBLANK($A3:$A100),"", ROUND($J3:J100 * M$1 / 9,0))} -> 68 | N3: {=IF(ISBLANK($A3:$A100),"", $K3:K100*4 + $L3:L100*4 + $M3:M100*9)} -> 2040 | O3: {=IF(ISBLANK($A3:$A100),"", $O$1)} -> 5 | P3: {=IF(ISBLANK($A3:$A100),"", ROUND($P$1 * $N3:$N100/1000,0))} -> 29 | Q3: {=IF(ISBLANK($A3:$A100),"", ROUND($N3:$N100 * Q$1 / 4,0))} -> 51 | R3: {=IF(ISBLANK($A3:$A100),"", ROUND($N3:$N100 * R$1 / 9,0))} -> 23 | S3: {=IF(ISBLANK($A3:$A100),"", $S$1)} -> 3.5 | T3: 0 | U3: 0 | V3: 0 | W3: 0 | X3: 0.05 | Y3: 0 | Z3: 0 | AA3: 0 | AB3: 0 | AC3: {=IF(ISBLANK($A3:$A100),"", J3:J100 * (1 + T3:T100))} -> 2039 | AD3: {=IF(ISBLANK($A3:$A100),"", ROUND($AC3:AC100 * K$1 / 4,0))} -> 153 | AE3: {=IF(ISBLANK($A3:$A100),"", ROUND($AC3:AC100 * L$1 / 4,0))} -> 204 | AF3: {=IF(ISBLANK($A3:$A100),"", ROUND($AC3:AC100 * M$1 / 9,0))} -> 68 | AG3: {=IF(ISBLANK($A3:$A100),"", ROUND($AD3:AD100 * (1 + U3:U100),0))} -> 153 | AH3: {=IF(ISBLANK($A3:$A100),"", ROUND($AE3:AE100 * (1 + V3:V100),0))} -> 204 | AI3: {=IF(ISBLANK($A3:$A100),"", ROUND($AF3:AF100 * (1 + W3:W100),0))} -> 68 | AJ3: {=IF(ISBLANK($A3:$A100),"", $AG3:AG100*4 + $AH3:AH100*4 + $AI3:AI100*9)} -> 2040 | AK3: {=IF(ISBLANK($A3:$A100),"", ROUND($O$1 * (1 + X3:X100),2))} -> 5.25 | AL3: {=IF(ISBLANK($A3:$A100),"", ROUND($P$1 * $AJ3:$AJ100/1000 * (1 + Y3:Y100),1))} -> 28.6 | AM3: {=IF(ISBLANK($A3:$A100),"", ROUND($AJ3:$AJ100 * $Q$1 / 4 * (1 + Z3:Z100),1))} -> 51 | AN3: {=IF(ISBLANK($A3:$A100),"", ROUND($AJ3:$AJ100 * $R$1 / 9 * (1 + AA3:AA100),1))} -> 22.7 | AO3: {=IF(ISBLANK($A3:$A100),"", $S$1 * (1 + AB3:AB100))} -> 3.5 | AQ3: Pasos | AR3: fuerza_a | AS3: {=IF(ISBLANK(A3:A100),"", ROUND(_xlfn.XLOOKUP($AQ3:AQ100, Actividad_calc!$B$3:$B$30, Actividad_calc!BU$3:BU$30, "") * $E3:E100,2))} -> #REF! | AT3: {=IF(ISBLANK(A3:A100),"", ROUND(_xlfn.XLOOKUP($AR3:AR100, Actividad_calc!$B$3:$B$30, Actividad_calc!BU$3:BU$30, "") * $E3:E100,2))} -> #REF! | AV3: {=IF(ISBLANK(A3:A100),"", ROUND(($J3:J100 + $AS3:AS100 + $AT3:AT100) * (1 + T3:T100),0))} -> #REF! | AW3: {=IF(ISBLANK(A3:A100),"", ROUND($AV3:AV100 * _xlfn.XLOOKUP($AR3:AR100, Actividad_calc!$B$3:$B$30, Actividad_calc!#REF!)/4,0))} -> #REF! | AX3: {=IF(ISBLANK(A3:A100),"", ROUND($AV3:AV100 * _xlfn.XLOOKUP($AR3:AR100, Actividad_calc!$B$3:$B$30, Actividad_calc!#REF!)/4,0))} -> #REF! | AY3: {=IF(ISBLANK(A3:A100),"", ROUND($AV3:AV100 * _xlfn.XLOOKUP($AR3:AR100, Actividad_calc!$B$3:$B$30, Actividad_calc!#REF!)/9,0))} -> #REF! | AZ3: {=IF(ISBLANK(A3:A100),"", ROUND(AW3:AW100 * (1 + U3:U100),0))} -> #REF! | BA3: {=IF(ISBLANK(A3:A100),"", ROUND(AX3:AX100 * (1 + V3:V100),0))} -> #REF! | BB3: {=IF(ISBLANK(A3:A100),"", ROUND(AY3:AY100 * (1 + W3:W100),0))} -> #REF! | BC3: {=IF(ISBLANK(A3:A100),"", $AZ3:AZ100*4 + $BA3:BA100*4 + $BB3:BB100*9)} -> #REF! | BD3: {=IF(ISBLANK($A3:$A100),"", ROUND($BD$1 * (1 + X3:X100),2))} -> 5.25 | BE3: {=IF(ISBLANK($A3:$A100),"", ROUND($BE$1 * $BC3:$BC100/1000 * (1 + Y3:Y100),1))} -> #REF! | BF3: {=IF(ISBLANK($A3:$A100),"", ROUND($BC3:$BC100 * $BF$1 / 4 * (1 + Z3:Z100),1))} -> #REF! | BG3: {=IF(ISBLANK($A3:$A100),"", ROUND($BC3:$BC100 * $BG$1 / 9 * (1 + AA3:AA100),1))} -> #REF! | BH3: {=IF(ISBLANK($A3:$A100),"", $BH$1 * (1 + AB3:AB100))} -> 3.5 | BJ3: menu | BK3: Lunes | BL3: {=_xlfn.XLOOKUP($BJ3:$BJ100&" | "&$BK3:$BK100, Alimentacion_calc!$A3:$A100&" | "&Alimentacion_calc!$B3:$B100, Alimentacion_calc!BK3:BK100, "")} -> 1601.5 | BM3: {=_xlfn.XLOOKUP($BJ3:$BJ100&" | "&$BK3:$BK100, Alimentacion_calc!$A3:$A100&" | "&Alimentacion_calc!$B3:$B100, Alimentacion_calc!BL3:BL100, "")} -> 121.6 | BN3: {=_xlfn.XLOOKUP($BJ3:$BJ100&" | "&$BK3:$BK100, Alimentacion_calc!$A3:$A100&" | "&Alimentacion_calc!$B3:$B100, Alimentacion_calc!BM3:BM100, "")} -> 147 | BO3: {=_xlfn.XLOOKUP($BJ3:$BJ100&" | "&$BK3:$BK100, Alimentacion_calc!$A3:$A100&" | "&Alimentacion_calc!$B3:$B100, Alimentacion_calc!BN3:BN100, "")} -> 62.2 | BP3: {=_xlfn.XLOOKUP($BJ3:$BJ100&" | "&$BK3:$BK100, Alimentacion_calc!$A3:$A100&" | "&Alimentacion_calc!$B3:$B100, Alimentacion_calc!BO3:BO100, "")} -> 19.85 | BQ3: {=_xlfn.XLOOKUP($BJ3:$BJ100&" | "&$BK3:$BK100, Alimentacion_calc!$A3:$A100&" | "&Alimentacion_calc!$B3:$B100, Alimentacion_calc!BP3:BP100, "")} -> 27 | BR3: {=_xlfn.XLOOKUP($BJ3:$BJ100&" | "&$BK3:$BK100, Alimentacion_calc!$A3:$A100&" | "&Alimentacion_calc!$B3:$B100, Alimentacion_calc!BQ3:BQ100, "")} -> 56.25 | BS3: {=_xlfn.XLOOKUP($BJ3:$BJ100&" | "&$BK3:$BK100, Alimentacion_calc!$A3:$A100&" | "&Alimentacion_calc!$B3:$B100, Alimentacion_calc!BR3:BR100, "")} -> 2.1438 | BT3: {=_xlfn.XLOOKUP($BJ3:$BJ100&" | "&$BK3:$BK100, Alimentacion_calc!$A3:$A100&" | "&Alimentacion_calc!$B3:$B100, Alimentacion_calc!BT3:BT100, "")} -> 2.2123 | BV3: {=IF($BL3:$BL100="","", IFERROR((BL3:BL100/BC3:BC100) - 1,"") )} | BW3: {=IF($BL3:$BL100="","", IFERROR((BM3:BM100/AZ3:AZ100) - 1,"") )} | BX3: {=IF($BL3:$BL100="","", IFERROR((BN3:BN100/BA3:BA100) - 1,"") )} | BY3: {=IF($BL3:$BL100="","", IFERROR((BO3:BO100/BB3:BB100) - 1,"") )} | BZ3: {=IF($BL3:$BL100="","", IFERROR((BS3:BS100/BD3:BD100) - 1,"") )} -> -0.59165714 | CA3: {=IF($BL3:$BL100="","", IFERROR((BQ3:BQ100/BE3:BE100) - 1,"") )} | CB3: {=IF($BL3:$BL100="","", IFERROR((BR3:BR100/BF3:BF100) - 1,"") )} | CC3: {=IF($BL3:$BL100="","", IFERROR((BP3:BP100/BG3:BG100) - 1,"") )} | CD3: {=IF($BL3:$BL100="","", IFERROR((BT3:BT100/BH3:BH100) - 1,"") )} -> -0.36791429 | CE3: {=_xlfn.BYROW(BV3:BV100, _xlfn.LAMBDA(_xlpm.fila, IF(_xlpm.fila="","", MIN(Alimentacion_score_data!B$4, ABS(_xlpm.fila) * IF(_xlpm.fila<0, Alimentacion_score_data!B$2, Alimentacion_score_data!B$3)) * 10 )))} | CF3: {=_xlfn.BYROW(BW3:BW100, _xlfn.LAMBDA(_xlpm.fila, IF(_xlpm.fila="","", MIN(Alimentacion_score_data!C$4, ABS(_xlpm.fila) * IF(_xlpm.fila<0, Alimentacion_score_data!C$2, Alimentacion_score_data!C$3)) * 10 )))} | CG3: {=_xlfn.BYROW(BX3:BX100, _xlfn.LAMBDA(_xlpm.fila, IF(_xlpm.fila="","", MIN(Alimentacion_score_data!D$4, ABS(_xlpm.fila) * IF(_xlpm.fila<0, Alimentacion_score_data!D$2, Alimentacion_score_data!D$3)) * 10 )))} | CH3: {=_xlfn.BYROW(BY3:BY100, _xlfn.LAMBDA(_xlpm.fila, IF(_xlpm.fila="","", MIN(Alimentacion_score_data!E$4, ABS(_xlpm.fila) * IF(_xlpm.fila<0, Alimentacion_score_data!E$2, Alimentacion_score_data!E$3)) * 10 )))} | CI3: {=_xlfn.BYROW(BZ3:BZ100, _xlfn.LAMBDA(_xlpm.fila, IF(_xlpm.fila="","", MIN(Alimentacion_score_data!F$4, ABS(_xlpm.fila) * IF(_xlpm.fila<0, Alimentacion_score_data!F$2, Alimentacion_score_data!F$3)) * 10 )))} -> 0 | CJ3: {=_xlfn.BYROW(CA3:CA100, _xlfn.LAMBDA(_xlpm.fila, IF(_xlpm.fila="","", MIN(Alimentacion_score_data!G$4, ABS(_xlpm.fila) * IF(_xlpm.fila<0, Alimentacion_score_data!G$2, Alimentacion_score_data!G$3)) * 10 )))} | CK3: {=_xlfn.BYROW(CB3:CB100, _xlfn.LAMBDA(_xlpm.fila, IF(_xlpm.fila="","", MIN(Alimentacion_score_data!H$4, ABS(_xlpm.fila) * IF(_xlpm.fila<0, Alimentacion_score_data!H$2, Alimentacion_score_data!H$3)) * 10 )))} | CL3: {=_xlfn.BYROW(CC3:CC100, _xlfn.LAMBDA(_xlpm.fila, IF(_xlpm.fila="","", MIN(Alimentacion_score_data!I$4, ABS(_xlpm.fila) * IF(_xlpm.fila<0, Alimentacion_score_data!I$2, Alimentacion_score_data!I$3)) * 10 )))} | CM3: {=_xlfn.BYROW(CD3:CD100, _xlfn.LAMBDA(_xlpm.fila, IF(_xlpm.fila="","", MIN(Alimentacion_score_data!J$4, ABS(_xlpm.fila) * IF(_xlpm.fila<0, Alimentacion_score_data!J$2, Alimentacion_score_data!J$3)) * 10 )))} -> 0 | CN3: {=IFERROR(ROUND(10 / (1+ ((CE3:CE100+CF3:CF100+CG3:CG100+CH3:CH100+CI3:CI100+CJ3:CJ100+CK3:CK100+CL3:CL100+CM3:CM100) / Alimentacion_score_data!$L$4)^Alimentacion_score_data!$L$3),4),"")}
A4: TC02 | B4: hombre | C4: 30 | D4: 175 | E4: 75 | G4: 24.5 | H4: 1699 | J4: 2039 | K4: 153 | L4: 204 | M4: 68 | N4: 2040 | O4: 5 | P4: 29 | Q4: 51 | R4: 23 | S4: 3.5 | T4: 0.05 | U4: 0.05 | V4: 0 | W4: 0 | X4: 0 | Y4: 0 | Z4: 0 | AA4: 0 | AB4: 0 | AC4: 2140.95 | AD4: 161 | AE4: 214 | AF4: 71 | AG4: 169 | AH4: 214 | AI4: 71 | AJ4: 2171 | AK4: 5 | AL4: 30.4 | AM4: 54.3 | AN4: 24.1 | AO4: 3.5 | AQ4: Pasos | AR4: fuerza_b | AS4: #REF! | AT4: #REF! | AV4: #REF! | AW4: #REF! | AX4: #REF! | AY4: #REF! | AZ4: #REF! | BA4: #REF! | BB4: #REF! | BC4: #REF! | BD4: 5 | BE4: #REF! | BF4: #REF! | BG4: #REF! | BH4: 3.5
A5: TC03 | B5: mujer | C5: 40 | D5: 165 | E5: 62 | G5: 22.8 | H5: 1290 | J5: 1548 | K5: 116 | L5: 155 | M5: 52 | N5: 1552 | O5: 5 | P5: 22 | Q5: 39 | R5: 17 | S5: 3.5 | T5: -0,10 | U5: 0 | V5: 0.05 | W5: 0.05 | X5: 0 | Y5: 0 | Z5: 0 | AA5: 0 | AB5: 0 | AC5: 1393.2 | AD5: 104 | AE5: 139 | AF5: 46 | AG5: 104 | AH5: 146 | AI5: 48 | AJ5: 1432 | AK5: 5 | AL5: 20 | AM5: 35.8 | AN5: 15.9 | AO5: 3.5 | AQ5: Pasos | AR5: fuerza_c | AS5: #REF! | AT5: #REF! | AV5: #REF! | AW5: #REF! | AX5: #REF! | AY5: #REF! | AZ5: #REF! | BA5: #REF! | BB5: #REF! | BC5: #REF! | BD5: 5 | BE5: #REF! | BF5: #REF! | BG5: #REF! | BH5: 3.5
A6: TC04 | B6: hombre | C6: 35 | D6: 180 | E6: 85 | G6: 26.2 | H6: 1805 | J6: 2166 | K6: 162 | L6: 217 | M6: 72 | N6: 2164 | O6: 5 | P6: 30 | Q6: 54 | R6: 24 | S6: 3.5 | T6: 0 | U6: 0 | V6: 0 | W6: 0 | X6: 0 | Y6: 0 | Z6: 0 | AA6: 0 | AB6: 0 | AC6: 2166 | AD6: 162 | AE6: 217 | AF6: 72 | AG6: 162 | AH6: 217 | AI6: 72 | AJ6: 2164 | AK6: 5 | AL6: 30.3 | AM6: 54.1 | AN6: 24 | AO6: 3.5 | AQ6: Pasos | AR6: descanso | AS6: #REF! | AT6: #REF! | AV6: #REF! | AW6: #REF! | AX6: #REF! | AY6: #REF! | AZ6: #REF! | BA6: #REF! | BB6: #REF! | BC6: #REF! | BD6: 5 | BE6: #REF! | BF6: #REF! | BG6: #REF! | BH6: 3.5
A7: TC05 | B7: hombre | C7: 28 | D7: 172 | E7: 70 | G7: 23.7 | H7: 1640 | J7: 1968 | K7: 148 | L7: 197 | M7: 66 | N7: 1974 | O7: 5 | P7: 28 | Q7: 49 | R7: 22 | S7: 3.5 | T7: 0 | U7: 0 | V7: 0 | W7: 0 | X7: 0 | Y7: 0 | Z7: 0 | AA7: 0 | AB7: 0 | AC7: 1968 | AD7: 148 | AE7: 197 | AF7: 66 | AG7: 148 | AH7: 197 | AI7: 66 | AJ7: 1974 | AK7: 5 | AL7: 27.6 | AM7: 49.4 | AN7: 21.9 | AO7: 3.5 | AQ7: Pasos | AR7: recuperacion | AS7: #REF! | AT7: #DIV/0! | AV7: #REF! | AW7: #REF! | AX7: #REF! | AY7: #REF! | AZ7: #REF! | BA7: #REF! | BB7: #REF! | BC7: #REF! | BD7: 5 | BE7: #REF! | BF7: #REF! | BG7: #REF! | BH7: 3.5
A8: TC06H | B8: hombre | C8: 43 | D8: 173 | E8: 80 | G8: 26.7 | H8: 1671 | J8: 2005 | K8: 150 | L8: 201 | M8: 67 | N8: 2007 | O8: 5 | P8: 28 | Q8: 50 | R8: 22 | S8: 3.5 | T8: -0.05 | U8: 0.05 | V8: 0 | W8: -0.05 | X8: 0 | Y8: 0 | Z8: 0 | AA8: 0 | AB8: 0 | AC8: 1904.75 | AD8: 143 | AE8: 190 | AF8: 63 | AG8: 150 | AH8: 190 | AI8: 60 | AJ8: 1900 | AK8: 5 | AL8: 26.6 | AM8: 47.5 | AN8: 21.1 | AO8: 3.5 | AQ8: Pasos | AR8: recuperacion | AS8: #REF! | AT8: #DIV/0! | AV8: #REF! | AW8: #REF! | AX8: #REF! | AY8: #REF! | AZ8: #REF! | BA8: #REF! | BB8: #REF! | BC8: #REF! | BD8: 5 | BE8: #REF! | BF8: #REF! | BG8: #REF! | BH8: 3.5 | BJ8: menu_1 | BK8: Martes
A9: TC06H | B9: hombre | C9: 43 | D9: 173 | E9: 80 | G9: 26.7 | H9: 1671 | J9: 2005 | K9: 150 | L9: 201 | M9: 67 | N9: 2007 | O9: 5 | P9: 28 | Q9: 50 | R9: 22 | S9: 3.5 | T9: -0.05 | U9: 0.05 | V9: 0 | W9: -0.05 | X9: 0 | Y9: 0 | Z9: 0 | AA9: 0 | AB9: 0 | AC9: 1904.75 | AD9: 143 | AE9: 190 | AF9: 63 | AG9: 150 | AH9: 190 | AI9: 60 | AJ9: 1900 | AK9: 5 | AL9: 26.6 | AM9: 47.5 | AN9: 21.1 | AO9: 3.5 | AQ9: Pasos | AR9: fuerza_a | AS9: #REF! | AT9: #REF! | AV9: #REF! | AW9: #REF! | AX9: #REF! | AY9: #REF! | AZ9: #REF! | BA9: #REF! | BB9: #REF! | BC9: #REF! | BD9: 5 | BE9: #REF! | BF9: #REF! | BG9: #REF! | BH9: 3.5 | BJ9: menu_1 | BK9: Lunes | BL9: 1466 | BM9: 139.96 | BN9: 128.39 | BO9: 47.74 | BP9: 14.21 | BQ9: 22.16 | BR9: 35.63 | BS9: 1.536 | BT9: 1.8344 | BZ9: -0.6928 | CD9: -0.47588571 | CI9: 0 | CM9: 0
A10: TC06H | B10: hombre | C10: 43 | D10: 173 | E10: 80 | G10: 26.7 | H10: 1671 | J10: 2005 | K10: 150 | L10: 201 | M10: 67 | N10: 2007 | O10: 5 | P10: 28 | Q10: 50 | R10: 22 | S10: 3.5 | T10: -0.05 | U10: 0.05 | V10: 0 | W10: -0.05 | X10: 0 | Y10: 0 | Z10: 0 | AA10: 0 | AB10: 0 | AC10: 1904.75 | AD10: 143 | AE10: 190 | AF10: 63 | AG10: 150 | AH10: 190 | AI10: 60 | AJ10: 1900 | AK10: 5 | AL10: 26.6 | AM10: 47.5 | AN10: 21.1 | AO10: 3.5 | AQ10: Pasos | AR10: fuerza_b | AS10: #REF! | AT10: #REF! | AV10: #REF! | AW10: #REF! | AX10: #REF! | AY10: #REF! | AZ10: #REF! | BA10: #REF! | BB10: #REF! | BC10: #REF! | BD10: 5 | BE10: #REF! | BF10: #REF! | BG10: #REF! | BH10: 3.5 | BJ10: menu_1 | BK10: Miércoles
A11: TC06H | B11: hombre | C11: 43 | D11: 173 | E11: 80 | G11: 26.7 | H11: 1671 | J11: 2005 | K11: 150 | L11: 201 | M11: 67 | N11: 2007 | O11: 5 | P11: 28 | Q11: 50 | R11: 22 | S11: 3.5 | T11: -0.05 | U11: 0.05 | V11: 0 | W11: -0.05 | X11: 0 | Y11: 0 | Z11: 0 | AA11: 0 | AB11: 0 | AC11: 1904.75 | AD11: 143 | AE11: 190 | AF11: 63 | AG11: 150 | AH11: 190 | AI11: 60 | AJ11: 1900 | AK11: 5 | AL11: 26.6 | AM11: 47.5 | AN11: 21.1 | AO11: 3.5 | AQ11: Pasos | AR11: fuerza_c | AS11: #REF! | AT11: #REF! | AV11: #REF! | AW11: #REF! | AX11: #REF! | AY11: #REF! | AZ11: #REF! | BA11: #REF! | BB11: #REF! | BC11: #REF! | BD11: 5 | BE11: #REF! | BF11: #REF! | BG11: #REF! | BH11: 3.5 | BJ11: menu_1 | BK11: Viernes | BL11: 1471.4 | BM11: 143.39 | BN11: 129.4 | BO11: 43.82 | BP11: 14.3 | BQ11: 20.4 | BR11: 44.67 | BS11: 1.6403 | BT11: 1.6954 | BZ11: -0.67194 | CD11: -0.5156 | CI11: 0 | CM11: 0
A12: TC06H | B12: hombre | C12: 43 | D12: 173 | E12: 80 | G12: 26.7 | H12: 1671 | J12: 2005 | K12: 150 | L12: 201 | M12: 67 | N12: 2007 | O12: 5 | P12: 28 | Q12: 50 | R12: 22 | S12: 3.5 | T12: -0.05 | U12: 0.05 | V12: 0 | W12: -0.05 | X12: 0 | Y12: 0 | Z12: 0 | AA12: 0 | AB12: 0 | AC12: 1904.75 | AD12: 143 | AE12: 190 | AF12: 63 | AG12: 150 | AH12: 190 | AI12: 60 | AJ12: 1900 | AK12: 5 | AL12: 26.6 | AM12: 47.5 | AN12: 21.1 | AO12: 3.5 | AQ12: Pasos | AR12: descanso | AS12: #REF! | AT12: #REF! | AV12: #REF! | AW12: #REF! | AX12: #REF! | AY12: #REF! | AZ12: #REF! | BA12: #REF! | BB12: #REF! | BC12: #REF! | BD12: 5 | BE12: #REF! | BF12: #REF! | BG12: #REF! | BH12: 3.5 | BJ12: menu_1 | BK12: Domingo

Sheet Actividad_data
A1: id | B1: name | C1: type | D1: focus | E1: muscles | F1: equipment | G1: relativeLoad | H1: met | I1: restSec | J1: description | K1: technique | L1: cadenceBase
A2: flexiones | B2: Flexiones | C2: fuerza | D2: tren_superior | E2: pecho, triceps, hombro | F2: ninguno | G2: 0.32 | H2: 6 | I2: 90 | J2: Empuje horizontal con control del core. | K2: El movimiento se realiza apoyando manos bajo el pecho, cuerpo en linea recta desde cabeza a talones, flexionando codos para bajar hasta que el pecho se acerque al suelo, manteniendo el core activo y la cadera estable, y empujando de nuevo hasta extender los brazos sin bloquear.
A3: press_banca | B3: Press banca | C3: fuerza | D3: tren_superior | E3: pecho, triceps, hombro | F3: banco, barra | G3: 0.42 | H3: 5.5 | I3: 120 | J3: Basico de empuje para fuerza e hipertrofia. | K3: El movimiento se realiza acostado en banco, con escápulas retraídas y pies firmes en el suelo; se baja la barra de forma controlada hasta el pecho medio, manteniendo los codos en un ángulo cómodo, y se empuja hacia arriba en línea recta sin perder la estabilidad del tronco.
A4: press_inclinado | B4: Press inclinado | C4: fuerza | D4: tren_superior | E4: pecho superior, hombro, triceps | F4: banco inclinado, mancuernas o barra | G4: 0.4 | H4: 5.5 | I4: 120 | J4: Enfasis en porcion superior del pectoral. | K4: El movimiento se realiza en banco inclinado (30-45 grados), bajando la carga de forma controlada hasta la parte alta del pecho y empujando hacia arriba sin bloquear los codos, manteniendo el tronco estable y las escápulas activas.
A5: aperturas_mancuernas | B5: Aperturas con mancuernas | C5: fuerza | D5: tren_superior | E5: pecho | F5: mancuernas, banco | G5: 0.22 | H5: 4 | I5: 60 | J5: Aislamiento del pectoral con rango amplio. | K5: El movimiento se realiza con codos ligeramente flexionados, abriendo los brazos en arco hasta sentir estiramiento del pectoral, manteniendo la tensión sin rebotar, y cerrando de nuevo arriba sin chocar las mancuernas.
A6: fondos_paralelas | B6: Fondos en paralelas | C6: fuerza | D6: tren_superior | E6: pecho, triceps, hombro | F6: paralelas | G6: 0.38 | H6: 6.5 | I6: 90 | J6: Empuje vertical con alto reclutamiento. | K6: El movimiento se realiza sujetando las paralelas con el cuerpo suspendido, inclinando ligeramente el tronco, flexionando codos para descender de forma controlada hasta un rango cómodo y empujando para extender sin balanceos.
A7: dominadas | B7: Dominadas | C7: fuerza | D7: tren_superior | E7: espalda, biceps, core | F7: barra dominadas | G7: 0.4 | H7: 7 | I7: 120 | J7: Traccion vertical con carga corporal. | K7: El movimiento se realiza colgado de la barra, activando las escápulas primero, elevando el cuerpo hasta que el pecho se acerque a la barra, y descendiendo controlado hasta extensión completa sin dejar que los hombros se colapsen.
A8: jalon_pecho | B8: Jalon al pecho | C8: fuerza | D8: tren_superior | E8: espalda, biceps | F8: polea | G8: 0.34 | H8: 5 | I8: 90 | J8: Alternativa a dominadas con carga regulable. | K8: El movimiento se realiza sentado con el tronco estable, tirando de la barra hacia la parte alta del pecho con codos hacia abajo y atrás, y retornando la carga lentamente sin perder la postura.
A9: remo_barra | B9: Remo con barra | C9: fuerza | D9: tren_superior | E9: espalda, biceps, core | F9: barra | G9: 0.42 | H9: 6 | I9: 90 | J9: Traccion horizontal para densidad de espalda. | K9: El movimiento se realiza en bisagra de cadera con espalda neutra, llevando la barra hacia el ombligo con codos cerca del cuerpo, y bajando controlado sin encorvar ni balancear.
A10: remo_mancuernas | B10: Remo con mancuerna | C10: fuerza | D10: tren_superior | E10: espalda, biceps | F10: mancuerna, banco | G10: 0.35 | H10: 5.5 | I10: 90 | J10: Trabajo unilateral para equilibrio y control. | K10: El movimiento se realiza apoyando una mano en el banco, con la espalda recta, llevando la mancuerna hacia la cadera con el codo pegado y bajando lentamente sin rotar el tronco.
A11: face_pull | B11: Face pull | C11: fuerza | D11: tren_superior | E11: deltoide posterior, espalda alta | F11: polea, cuerda | G11: 0.2 | H11: 4 | I11: 60 | J11: Salud del hombro y postura. | K11: El movimiento se realiza tirando de la cuerda hacia la cara, con codos altos y separados, llevando las manos a la altura de las orejas y contrayendo la espalda alta antes de volver controlado.
A12: press_militar | B12: Press militar | C12: fuerza | D12: tren_superior | E12: hombro, triceps, core | F12: barra o mancuernas | G12: 0.4 | H12: 6 | I12: 90 | J12: Empuje vertical de pie. | K12: El movimiento se realiza de pie, con glúteos y abdomen activos, empujando la barra desde el pecho hacia arriba en línea recta, evitando arquear la zona lumbar, y bajando de forma controlada.
A13: elevaciones_laterales | B13: Elevaciones laterales | C13: fuerza | D13: tren_superior | E13: deltoide lateral | F13: mancuernas | G13: 0.2 | H13: 4 | I13: 60 | J13: Aislamiento de hombro para amplitud. | K13: El movimiento se realiza con codos semidoblados, elevando los brazos hasta la altura del hombro sin balanceo, y descendiendo lentamente manteniendo la tensión.
... A34: kettlebell_swing | B34: Kettlebell swing | C34: fuerza | D34: full_body | E34: gluteo, isquios, core | F34: kettlebell | G34: 0.35 | H34: 8 | I34: 90 | J34: Bisagra de cadera con ritmo. | K34: El movimiento se realiza con bisagra de cadera, espalda neutra, llevando la pesa atrás y proyectándola al frente con la potencia de glúteos, sin tirar con los brazos.
A35: caminar | B35: Caminar | C35: cardio | D35: full_body | E35: piernas, core | F35: ninguno | H35: 3.5 | I35: 0 | J35: Actividad base de baja intensidad. | K35: El movimiento se realiza con paso constante, postura erguida, brazos relajados y apoyo suave del pie. | L35: 100
A36: correr | B36: Correr | C36: cardio | D36: full_body | E36: piernas, core | F36: ninguno | H36: 9.8 | I36: 0 | J36: Cardio continuo de impacto moderado. | K36: El movimiento se realiza con zancada corta, apoyo medio pie, cadencia estable y tronco ligeramente inclinado hacia delante. | L36: 170
A37: hiit | B37: HIIT | C37: cardio | D37: full_body | E37: cuerpo completo | F37: variable | H37: 10.5 | I37: 0 | J37: Intervalos cortos de alta intensidad. | K37: El trabajo se realiza alternando intervalos de esfuerzo muy alto con descansos activos o completos, cuidando la técnica en cada ejercicio. | L37: 160
A38: saltar_cuerda | B38: Saltar cuerda | C38: cardio | D38: full_body | E38: piernas, hombro, core | F38: cuerda | H38: 11.5 | I38: 0 | J38: Cardio coordinativo y rapido. | K38: El movimiento se realiza con saltos bajos y rápidos, girando la cuerda con las muñecas, manteniendo codos cerca del cuerpo y postura relajada. | L38: 120
A39: jumping_jacks | B39: Jumping jacks | C39: cardio | D39: full_body | E39: piernas, hombro, core | F39: ninguno | H39: 8 | I39: 0 | J39: Calentamiento dinamico y cardio suave. | K39: El movimiento se realiza abriendo y cerrando piernas mientras los brazos suben y bajan, aterrizando suave y controlado. | L39: 100
A40: mountain_climbers | B40: Mountain climbers | C40: cardio | D40: full_body | E40: core, hombro, piernas | F40: ninguno | H40: 9 | I40: 0 | J40: Cardio en suelo con foco en core. | K40: El movimiento se realiza en posición de plancha, llevando rodillas alternas al pecho con ritmo, manteniendo hombros sobre manos y cadera estable. | L40: 120
A41: bicicleta_carretera | B41: Bicicleta carretera | C41: cardio | D41: tren_inferior | E41: piernas | F41: bicicleta | H41: 8 | I41: 0 | J41: Cardio continuo en ruta. | K41: El movimiento se realiza con cadencia estable, postura relajada, core activo y ajustes de marcha según el terreno. | L41: 80
A42: bicicleta_montana | B42: Bicicleta montana | C42: cardio | D42: tren_inferior | E42: piernas, core | F42: bicicleta | H42: 10 | I42: 0 | J42: Mayor demanda por desnivel y terreno. | K42: El movimiento se realiza anticipando el terreno, usando cambios adecuados y distribuyendo el peso para mantener tracción. | L42: 70
A43: spinning | B43: Spinning | C43: cardio | D43: tren_inferior | E43: piernas | F43: bicicleta estatica | H43: 8.5 | I43: 0 | J43: Intervalos en bici estatica. | K43: El trabajo se realiza manteniendo cadencia, ajustando resistencia según intervalos y evitando balancear el tronco. | L43: 90
A44: eliptica | B44: Eliptica | C44: cardio | D44: tren_inferior | E44: piernas | F44: maquina eliptica | H44: 6.5 | I44: 0 | J44: Cardio bajo impacto. | K44: El movimiento se realiza con zancada fluida, sin bloquear rodillas y manteniendo el tronco estable. | L44: 140
A45: escaladora | B45: Escaladora | C45: cardio | D45: tren_inferior | E45: piernas, gluteo | F45: maquina escaladora | H45: 8.8 | I45: 0 | J45: Simula subir escaleras. | K45: El movimiento se realiza con paso completo, apoyando todo el pie y sin apoyarse en exceso en los brazos. | L45: 90
A46: trekking | B46: Trekking | C46: cardio | D46: tren_inferior | E46: piernas, core | F46: ninguno | H46: 6.5 | I46: 0 | J46: Caminata en terreno irregular. | K46: El movimiento se realiza con paso firme y regular, cuidando la postura y usando bastones si hay desnivel. | L46: 100
... A53: movilidad_articular | B53: Movilidad articular | C53: cardio | D53: movilidad | E53: articulaciones | F53: ninguno | H53: 2 | I53: 0 | J53: Rutina corta para preparar el cuerpo. | K53: El trabajo se realiza con movimientos circulares controlados, recorriendo todo el rango articular sin dolor. | L53: 50

Sheet Actividad_calc
D1: EJERCICIO_1 | J1: EJERCICIO_2 | Q1: EJERCICIO_3 | X1: EJERCICIO_4 | AE1: EJERCICIO_5 | AL1: EJERCICIO_6 | AS1: EJERCICIO_7 | AZ1: EJERCICIO_8 | BG1: EJERCICIO_9 | BN1: EJERCICIO_10 | BV1: 80
A2: case_id | B2: activity_id | D2: activity_name_1 | E2: sets_1 | F2: reps_1 | G2: weightKg_1 | H2: secPerRep | I2: energy_perkg_1 | J2: activity_name_2 | K2: series_time_2 | L2: rep_2 | M2: weight_2 | N2: rep_time_2 | O2: rest_time_2 | P2: energy_perkg_1 | Q2: activity_name_3 | R2: series_time_3 | S2: rep_3 | T2: weight_3 | U2: rep_time_3 | V2: rest_time_4 | W2: energy_perkg_1 | X2: activity_name_4 | Y2: series_time_4 | Z2: rep_4 | AA2: weight_4 | AB2: rep_time_4 | AC2: rest_time_4 | AD2: energy_perkg_1 | AE2: activity_name_5 | AF2: series_time_5 | AG2: rep_5 | AH2: weight_5 | AI2: rep_time_5 | AJ2: rest_time_5 | AK2: energy_perkg_1 | AL2: activity_name_6 | AM2: series_time_6 | AN2: rep_6 | AO2: weight_6 | AP2: rep_time_6 | AQ2: rest_time_6 | AR2: energy_perkg_1 | AS2: activity_name_7 | AT2: series_time_7 | AU2: rep_7 | AV2: weight_7 | AW2: rep_time_7 | AX2: rest_time_7 | AY2: energy_perkg_1 | AZ2: activity_name_8 | BA2: series_time_8 | BB2: rep_8 | BC2: weight_8 | BD2: rep_time_8 | BE2: rest_time_8 | BF2: energy_perkg_1 | BG2: activity_name_9 | BH2: series_time_9 | BI2: rep_9 | BJ2: weight_9 | BK2: rep_time_9 | BL2: rest_time_9 | BM2: energy_perkg_1 | BN2: activity_name_10 | BO2: series_time_10 | BP2: rep_10 | BQ2: weight_10 | BR2: rep_time_10 | BS2: rest_time_10 | BT2: energy_perkg_1 | BU2: activity_total_energy_per_kg
A3: TC06H | B3: descanso | I3: {=IF(ISBLANK($B3:$B100),"",_xlfn.LET( _xlpm.peso_usuario, _xlfn.XLOOKUP($A3:$A100, Objetivos_calc!$A3:$A100, Objetivos_calc!$E3:$E100, ""), _xlpm.met, _xlfn.XLOOKUP(D3:D100, Actividad_data!$B2:$B100, Actividad_data!$H2:$H100, ""), _xlpm.carga_relativa, _xlfn.XLOOKUP(D3:D100, Actividad_data!$B2:$B100, Actividad_data!$G2:$G100, ""), _xlpm.factor_reps, 0.7 + (0.8 * 1 / (1 + F3:F100 / 30)), _xlpm.factor_trabajo, 1 + (1 / (1 + ((_xlpm.carga_relativa / ( (G3:G100 / _xlpm.peso_usuario) * (1 / (1 + F3:F100 / 30)) ) ) - 1) / 2 ) - 1), _xlpm.factor_intensidad, _xlpm.factor_reps * _xlpm.factor_trabajo, _xlpm.min_trabajo, E3:E100 * F3:F100 * IF(H3:H100="",#REF!, H3:H100) / 60, _xlpm.min_descan, (E3:E100 - 1) * IF(#REF!="",#REF!,#REF!) / 60, _xlpm.kcals_trabajo, _xlpm.min_trabajo * _xlpm.peso_usuario * _xlpm.met * _xlpm.factor_intensidad / 60, _xlpm.kcals_descan, _xlpm.min_descan * _xlpm.peso_usuario * 1.5 / 60, _xlpm.kcals_trabajo + _xlpm.kcals_descan ))} -> #REF! | P3: {=IF(ISBLANK($B3:$B100),"", _xlfn.LET( _xlpm.met, _xlfn.XLOOKUP(J3:J100, Actividad_data!#REF!, Actividad_data!$F$2:$F$100,""), _xlpm.factor_intensidad, IFERROR(0.7 + 0.8 * (M3:M100 / (M3:M100 * (1 + L3:L100 / 30))),1), _xlpm.min_trabajo, K3:K100 * L3:L100 * IF(N3:N100="",#REF!,N3:N100) / 60, _xlpm.min_descan, (K3:K100 - 1) * IF(O3:O100="",#REF!,O3:O100) / 60, _xlpm.kcals_kg_trabajo, _xlpm.min_trabajo * _xlpm.met * _xlpm.factor_intensidad / 60, _xlpm.kcals_kg_descan, _xlpm.min_descan * 1.5 / 60, _xlpm.kcals_kg_trabajo + _xlpm.kcals_kg_descan ))} -> #REF! | W3: {=IF(ISBLANK($B3:$B100),"", _xlfn.LET( _xlpm.met, _xlfn.XLOOKUP(Q3:Q100, Actividad_data!#REF!, Actividad_data!$F$2:$F$100,""), _xlpm.factor_intensidad, IFERROR(0.7 + 0.8 * (T3:T100 / (T3:T100 * (1 + S3:S100 / 30))),1), _xlpm.min_trabajo, R3:R100 * S3:S100 * IF(U3:U100="",#REF!,U3:U100) / 60, _xlpm.min_descan, (R3:R100 - 1) * IF(V3:V100="",#REF!,V3:V100) / 60, _xlpm.kcals_kg_trabajo, _xlpm.min_trabajo * _xlpm.met * _xlpm.factor_intensidad / 60, _xlpm.kcals_kg_descan, _xlpm.min_descan * 1.5 / 60, _xlpm.kcals_kg_trabajo + _xlpm.kcals_kg_descan ))} -> #REF! | AD3: {=IF(ISBLANK($B3:$B100),"", _xlfn.LET( _xlpm.met, _xlfn.XLOOKUP(X3:X100, Actividad_data!#REF!, Actividad_data!$F$2:$F$100,""), _xlpm.factor_intensidad, IFERROR(0.7 + 0.8 * (AA3:AA100 / (AA3:AA100 * (1 + Z3:Z100 / 30))),1), _xlpm.min_trabajo, Y3:Y100 * Z3:Z100 * IF(AB3:AB100="",#REF!,AB3:AB100) / 60, _xlpm.min_descan, (Y3:Y100 - 1) * IF(AC3:AC100="",#REF!,AC3:AC100) / 60, _xlpm.kcals_kg_trabajo, _xlpm.min_trabajo * _xlpm.met * _xlpm.factor_intensidad / 60, _xlpm.kcals_kg_descan, _xlpm.min_descan * 1.5 / 60, _xlpm.kcals_kg_trabajo + _xlpm.kcals_kg_descan ))} -> #REF! | AK3: {=IF(ISBLANK($B3:$B100),"", _xlfn.LET( _xlpm.met, _xlfn.XLOOKUP(AE3:AE100, Actividad_data!#REF!, Actividad_data!$F$2:$F$100,""), _xlpm.factor_intensidad, IFERROR(0.7 + 0.8 * (AH3:AH100 / (AH3:AH100 * (1 + AG3:AG100 / 30))),1), _xlpm.min_trabajo, AF3:AF100 * AG3:AG100 * IF(AI3:AI100="",#REF!,AI3:AI100) / 60, _xlpm.min_descan, (AF3:AF100 - 1) * IF(AJ3:AJ100="",#REF!,AJ3:AJ100) / 60, _xlpm.kcals_kg_trabajo, _xlpm.min_trabajo * _xlpm.met * _xlpm.factor_intensidad / 60, _xlpm.kcals_kg_descan, _xlpm.min_descan * 1.5 / 60, _xlpm.kcals_kg_trabajo + _xlpm.kcals_kg_descan ))} -> #REF! | AR3: {=IF(ISBLANK($B3:$B100),"", _xlfn.LET( _xlpm.met, _xlfn.XLOOKUP(AL3:AL100, Actividad_data!#REF!, Actividad_data!$F$2:$F$100,""), _xlpm.factor_intensidad, IFERROR(0.7 + 0.8 * (AO3:AO100 / (AO3:AO100 * (1 + AN3:AN100 / 30))),1), _xlpm.min_trabajo, AM3:AM100 * AN3:AN100 * IF(AP3:AP100="",#REF!,AP3:AP100) / 60, _xlpm.min_descan, (AM3:AM100 - 1) * IF(AQ3:AQ100="",#REF!,AQ3:AQ100) / 60, _xlpm.kcals_kg_trabajo, _xlpm.min_trabajo * _xlpm.met * _xlpm.factor_intensidad / 60, _xlpm.kcals_kg_descan, _xlpm.min_descan * 1.5 / 60, _xlpm.kcals_kg_trabajo + _xlpm.kcals_kg_descan ))} -> #REF! | AY3: {=IF(ISBLANK($B3:$B100),"", _xlfn.LET( _xlpm.met, _xlfn.XLOOKUP(AS3:AS100, Actividad_data!#REF!, Actividad_data!$F$2:$F$100,""), _xlpm.factor_intensidad, IFERROR(0.7 + 0.8 * (AV3:AV100 / (AV3:AV100 * (1 + AU3:AU100 / 30))),1), _xlpm.min_trabajo, AT3:AT100 * AU3:AU100 * IF(AW3:AW100="",#REF!,AW3:AW100) / 60, _xlpm.min_descan, (AT3:AT100 - 1) * IF(AX3:AX100="",#REF!,AX3:AX100) / 60, _xlpm.kcals_kg_trabajo, _xlpm.min_trabajo * _xlpm.met * _xlpm.factor_intensidad / 60, _xlpm.kcals_kg_descan, _xlpm.min_descan * 1.5 / 60, _xlpm.kcals_kg_trabajo + _xlpm.kcals_kg_descan ))} -> #REF! | BF3: {=IF(ISBLANK($B3:$B100),"", _xlfn.LET( _xlpm.met, _xlfn.XLOOKUP(AZ3:AZ100, Actividad_data!#REF!, Actividad_data!$F$2:$F$100,""), _xlpm.factor_intensidad, IFERROR(0.7 + 0.8 * (BC3:BC100 / (BC3:BC100 * (1 + BB3:BB100 / 30))),1), _xlpm.min_trabajo, BA3:BA100 * BB3:BB100 * IF(BD3:BD100="",#REF!,BD3:BD100) / 60, _xlpm.min_descan, (BA3:BA100 - 1) * IF(BE3:BE100="",#REF!,BE3:BE100) / 60, _xlpm.kcals_kg_trabajo, _xlpm.min_trabajo * _xlpm.met * _xlpm.factor_intensidad / 60, _xlpm.kcals_kg_descan, _xlpm.min_descan * 1.5 / 60, _xlpm.kcals_kg_trabajo + _xlpm.kcals_kg_descan ))} -> #REF! | BM3: {=IF(ISBLANK($B3:$B100),"", _xlfn.LET( _xlpm.met, _xlfn.XLOOKUP(BG3:BG100, Actividad_data!#REF!, Actividad_data!$F$2:$F$100,""), _xlpm.factor_intensidad, IFERROR(0.7 + 0.8 * (BJ3:BJ100 / (BJ3:BJ100 * (1 + BI3:BI100 / 30))),1), _xlpm.min_trabajo, BH3:BH100 * BI3:BI100 * IF(BK3:BK100="",#REF!,BK3:BK100) / 60, _xlpm.min_descan, (BH3:BH100 - 1) * IF(BL3:BL100="",#REF!,BL3:BL100) / 60, _xlpm.kcals_kg_trabajo, _xlpm.min_trabajo * _xlpm.met * _xlpm.factor_intensidad / 60, _xlpm.kcals_kg_descan, _xlpm.min_descan * 1.5 / 60, _xlpm.kcals_kg_trabajo + _xlpm.kcals_kg_descan ))} -> #REF! | BT3: {=IF(ISBLANK($B3:$B100),"", _xlfn.LET( _xlpm.met, _xlfn.XLOOKUP(BN3:BN100, Actividad_data!#REF!, Actividad_data!$F$2:$F$100,""), _xlpm.factor_intensidad, IFERROR(0.7 + 0.8 * (BQ3:BQ100 / (BQ3:BQ100 * (1 + BP3:BP100 / 30))),1), _xlpm.min_trabajo, BO3:BO100 * BP3:BP100 * IF(BR3:BR100="",#REF!,BR3:BR100) / 60, _xlpm.min_descan, (BO3:BO100 - 1) * IF(BS3:BS100="",#REF!,BS3:BS100) / 60, _xlpm.kcals_kg_trabajo, _xlpm.min_trabajo * _xlpm.met * _xlpm.factor_intensidad / 60, _xlpm.kcals_kg_descan, _xlpm.min_descan * 1.5 / 60, _xlpm.kcals_kg_trabajo + _xlpm.kcals_kg_descan ))} -> #REF! | BU3: {=IF(ISBLANK($B3:$B100),"", I3:I100 + P3:P100 + W3:W100 + AD3:AD100 + AK3:AK100 + AR3:AR100 + AY3:AY100 + BF3:BF100 + BM3:BM100 + BT3:BT100)} -> #REF! | BV3: =ROUND(BU3 * $BV$1,0) -> #REF!
A4: TC06H | B4: recuperacion | D4: Movilidad articular | E4: 1 | F4: 1 | H4: 360 | I4: #DIV/0! | J4: Estiramientos | K4: 1 | L4: 1 | N4: 480 | P4: #REF! | W4: #REF! | AD4: #REF! | AK4: #REF! | AR4: #REF! | AY4: #REF! | BF4: #REF! | BM4: #REF! | BT4: #REF! | BU4: #DIV/0! | BV4: =ROUND(BU4 * $BV$1,0) -> #DIV/0!
A5: TC06H | B5: pasos | D5: Caminar | E5: 1 | F5: 1 | G5: 8000 | H5: 100 | I5: #REF! | P5: #REF! | W5: #REF! | AD5: #REF! | AK5: #REF! | AR5: #REF! | AY5: #REF! | BF5: #REF! | BM5: #REF! | BT5: #REF! | BU5: #REF! | BV5: =ROUND(BU5 * $BV$1,0) -> #REF!
A6: TC06H | B6: fuerza_a | D6: Press banca | E6: 4 | F6: 8 | G6: 30 | H6: 4 | I6: #REF! | J6: Remo con barra | K6: 4 | L6: 10 | M6: 30 | N6: 4 | O6: 90 | P6: #REF! | Q6: Press militar | R6: 3 | S6: 9 | T6: 20 | U6: 4 | V6: 90 | W6: #REF! | X6: Sentadilla | Y6: 4 | Z6: 8 | AA6: 40 | AB6: 5 | AC6: 120 | AD6: #REF! | AE6: Peso muerto rumano | AF6: 3 | AG6: 10 | AH6: 40 | AI6: 4 | AJ6: 120 | AK6: #REF! | AL6: Elevacion de gemelos | AM6: 3 | AN6: 13 | AO6: 30 | AP6: 3 | AQ6: 60 | AR6: #REF! | AS6: Plancha | AT6: 1 | AU6: 1 | AW6: 180 | AY6: #REF! | AZ6: Crunch | BA6: 3 | BB6: 16 | BD6: 2 | BE6: 45 | BF6: #REF! | BG6: Movilidad articular | BH6: 1 | BI6: 1 | BK6: 360 | BM6: #REF! | BN6: Estiramientos | BO6: 1 | BP6: 1 | BR6: 240 | BT6: #REF! | BU6: #REF! | BV6: =ROUND(BU6 * $BV$1,0) -> #REF!
A7: TC06H | B7: fuerza_b | D7: Press inclinado | E7: 4 | F7: 8 | G7: 30 | H7: 4 | I7: #REF! | J7: Remo con mancuerna | K7: 3 | L7: 10 | M7: 20 | N7: 4 | O7: 90 | P7: #REF! | Q7: Press militar | R7: 3 | S7: 9 | T7: 20 | U7: 4 | V7: 90 | W7: #REF! | X7: Elevaciones laterales | Y7: 3 | Z7: 13 | AA7: 8 | AB7: 3 | AC7: 60 | AD7: #REF! | AE7: Curl biceps | AF7: 3 | AG7: 11 | AH7: 10 | AI7: 3 | AJ7: 60 | AK7: #REF! | AL7: Extension triceps | AM7: 3 | AN7: 11 | AO7: 15 | AP7: 3 | AQ7: 60 | AR7: #REF! | AS7: Plancha lateral | AT7: 1 | AU7: 1 | AW7: 240 | AY7: #REF! | AZ7: Russian twist | BA7: 3 | BB7: 20 | BC7: 5 | BD7: 2 | BE7: 45 | BF7: #REF! | BG7: Movilidad articular | BH7: 1 | BI7: 1 | BK7: 360 | BM7: #REF! | BN7: Estiramientos | BO7: 1 | BP7: 1 | BR7: 240 | BT7: #REF! | BU7: #REF! | BV7: =ROUND(BU7 * $BV$1,0) -> #REF!
A8: TC06H | B8: fuerza_c | D8: Sentadilla goblet | E8: 4 | F8: 10 | G8: 20 | H8: 4 | I8: #REF! | J8: Peso muerto | K8: 4 | L8: 7 | M8: 50 | N8: 5 | O8: 150 | P8: #REF! | Q8: Zancadas | R8: 3 | S8: 11 | T8: 12 | U8: 4 | V8: 90 | W8: #REF! | X8: Hip thrust | Y8: 3 | Z8: 10 | AA8: 40 | AB8: 4 | AC8: 120 | AD8: #REF! | AE8: Prensa de piernas | AF8: 3 | AG8: 11 | AH8: 80 | AI8: 4 | AJ8: 120 | AK8: #REF! | AL8: Elevacion de gemelos | AM8: 3 | AN8: 13 | AO8: 30 | AP8: 3 | AQ8: 60 | AR8: #REF! | AS8: Plancha | AT8: 1 | AU8: 1 | AW8: 180 | AY8: #REF! | AZ8: Elevaciones de piernas | BA8: 3 | BB8: 13 | BD8: 2 | BE8: 45 | BF8: #REF! | BG8: Movilidad articular | BH8: 1 | BI8: 1 | BK8: 360 | BM8: #REF! | BN8: Estiramientos | BO8: 1 | BP8: 1 | BR8: 240 | BT8: #REF! | BU8: #REF! | BV8: =ROUND(BU8 * $BV$1,0) -> #REF!

Sheet Alimentacion_data
A1: id | B1: name | C1: category | D1: unit | E1: nutrition_unit | F1: kcal | G1: protein | H1: carbs | I1: fat | J1: saturated_fat | K1: fiber | L1: sugar | M1: sodium | N1: processed
A2: acelga | B2: Acelga | C2: 🥔 Verduras y hortalizas | D2: g | E2: 100g | F2: 19 | G2: 1.8 | H2: 3.7 | I2: 0.2 | J2: 0 | K2: 1.6 | L2: 1.1 | M2: 210 | N2: 0
A3: ajo | B3: Ajo | C3: 🥔 Verduras y hortalizas | D3: g | E3: 100g | F3: 149 | G3: 6.4 | H3: 33.1 | I3: 0.5 | J3: 0.1 | K3: 2.1 | L3: 1 | M3: 17 | N3: 0
A4: alcachofa | B4: Alcachofa | C4: 🥔 Verduras y hortalizas | D4: g | E4: 100g | F4: 47 | G4: 3.3 | H4: 10.5 | I4: 0.2 | J4: 0 | K4: 5.4 | L4: 1 | M4: 94 | N4: 0
A5: apio | B5: Apio | C5: 🥔 Verduras y hortalizas | D5: g | E5: 100g | F5: 16 | G5: 0.7 | H5: 3 | I5: 0.2 | J5: 0 | K5: 1.6 | L5: 1.3 | M5: 80 | N5: 0
A6: berenjena | B6: Berenjena | C6: 🥔 Verduras y hortalizas | D6: g | E6: 100g | F6: 25 | G6: 1 | H6: 6 | I6: 0.2 | J6: 0 | K6: 3 | L6: 3.5 | M6: 2 | N6: 0
A7: brocoli | B7: Brócoli | C7: 🥔 Verduras y hortalizas | D7: g | E7: 100g | F7: 34 | G7: 2.8 | H7: 6.6 | I7: 0.4 | J7: 0.1 | K7: 2.6 | L7: 1.7 | M7: 33 | N7: 0
A8: calabacin | B8: Calabacín | C8: 🥔 Verduras y hortalizas | D8: g | E8: 100g | F8: 17 | G8: 1.2 | H8: 3.1 | I8: 0.3 | J8: 0.1 | K8: 1 | L8: 2.5 | M8: 8 | N8: 0
A9: calabaza | B9: Calabaza | C9: 🥔 Verduras y hortalizas | D9: g | E9: 100g | F9: 26 | G9: 1 | H9: 6.5 | I9: 0.1 | J9: 0 | K9: 0.5 | L9: 2.8 | M9: 1 | N9: 0
A10: cebolla | B10: Cebolla | C10: 🥔 Verduras y hortalizas | D10: g | E10: 100g | F10: 40 | G10: 1.1 | H10: 9.3 | I10: 0.1 | J10: 0 | K10: 1.7 | L10: 4.2 | M10: 4 | N10: 0
A11: champinones | B11: Champiñones | C11: 🥔 Verduras y hortalizas | D11: g | E11: 100g | F11: 22 | G11: 3.1 | H11: 3.3 | I11: 0.3 | J11: 0.1 | K11: 1 | L11: 2 | M11: 5 | N11: 0
A12: col | B12: Col | C12: 🥔 Verduras y hortalizas | D12: g | E12: 100g | F12: 25 | G12: 1.3 | H12: 5.8 | I12: 0.1 | J12: 0 | K12: 2.5 | L12: 3.2 | M12: 18 | N12: 0
A13: col_rizada | B13: Col rizada (kale) | C13: 🥔 Verduras y hortalizas | D13: g | E13: 100g | F13: 49 | G13: 4.3 | H13: 8.8 | I13: 0.9 | J13: 0.1 | K13: 3.6 | L13: 2.3 | M13: 38 | N13: 0
... A166: proteina_caseina | B166: Proteína caseína | C166: 💊 Suplementos | D166: g | E166: 100g | F166: 370 | G166: 82 | H166: 7 | I166: 2.5 | J166: 1.2 | K166: 0 | L166: 4 | M166: 420 | N166: 7

Sheet Alimentacion_calc
C1: DESAYUNO | W1: COMIDA | AQ1: CENA | BK1: TOTALES
A2: menu_id | B2: day_week | C2: breakfast_name_1 | D2: breakfast_quantity_1 | E2: breakfast_name_2 | F2: breakfast_quantity_2 | G2: breakfast_name_3 | H2: breakfast_quantity_3 | I2: breakfast_name_4 | J2: breakfast_quantity_4 | K2: breakfast_name_5 | L2: breakfast_quantity_5 | M2: breakfast_energy | N2: breakfast_prote | O2: breakfast_carboh | P2: breakfast_fats | Q2: breakfast_satfats | R2: breakfast_fiber | S2: breakfast_sugar | T2: breakfast_salt | U2: breakfast_processed_ratio_energy | V2: breakfast_processed_ratio | W2: lunch_name_1 | X2: lunch_quantity_1 | Y2: lunch_name_2 | Z2: lunch_quantity_2 | AA2: lunch_name_3 | AB2: lunch_quantity_3 | AC2: lunch_name_4 | AD2: lunch_quantity_4 | AE2: lunch_name_5 | AF2: lunch_quantity_5 | AG2: lunch_energy | AH2: lunch_prote | AI2: lunch_carboh | AJ2: lunch_fats | AK2: lunch_satfats | AL2: lunch_fiber | AM2: lunch_sugar | AN2: lunch_salt | AO2: lunch_processed_ratio_energy | AP2: lunch_processed_ratio | AQ2: dinner_name_1 | AR2: dinner_quantity_1 | AS2: dinner_name_2 | AT2: dinner_quantity_2 | AU2: dinner_name_3 | AV2: dinner_quantity_3 | AW2: dinner_name_4 | AX2: dinner_quantity_4 | AY2: dinner_name_5 | AZ2: dinner_quantity_5 | BA2: dinner_energy | BB2: dinner_prote | BC2: dinner_carboh | BD2: dinner_fats | BE2: dinner_satfats | BF2: dinner_fiber | BG2: dinner_sugar | BH2: dinner_salt | BI2: dinner_processed_ratio_energy | BJ2: dinner_processed_ratio | BK2: foot_total_energy | BL2: food_total_prote | BM2: food_total_carboh | BN2: food_total_fats | BO2: food_total_satfats | BP2: food_total_fiber | BQ2: food_total_sugar | BR2: food_total_salt | BS2: food_total_processed_ratio_energy | BT2: food_total_processed_ratio
